{
  "ID": "oval:org.debian:def:20095010",
  "Class": "vulnerability",
  "Metadata": {
    "Title": "CVE-2009-5010",
    "AffectedList": [
      {
        "Family": "unix",
        "Platform": "Debian GNU/Linux 9",
        "Product": "python-pyftpdlib"
      }
    ],
    "References": [
      {
        "Source": "CVE",
        "RefID": "CVE-2009-5010",
        "RefURL": "https://cve.mitre.org/cgi-bin/cvename.cgi?name=CVE-2009-5010"
      }
    ],
    "Description": "Race condition in the FTPHandler class in ftpserver.py in pyftpdlib before 0.5.1 allows remote attackers to cause a denial of service (daemon outage) by establishing and then immediately closing a TCP connection, leading to the accept function having an unexpected return value of None, a different vulnerability than CVE-2010-3494.",
    "Debian": {
      "MoreInfo": ""
    }
  },
  "Criteria": {
    "Operator": "AND",
    "Criterias": [
      {
        "Operator": "OR",
        "Criterias": [
          {
            "Operator": "AND",
            "Criterias": null,
            "Criterions": [
              {
                "Negate": false,
                "TestRef": "oval:org.debian.oval:tst:2",
                "Comment": "all architecture"
              },
              {
                "Negate": false,
                "TestRef": "oval:org.debian.oval:tst:3612",
                "Comment": "python-pyftpdlib DPKG is earlier than 0"
              }
            ]
          }
        ],
        "Criterions": null
      }
    ],
    "Criterions": [
      {
        "Negate": false,
        "TestRef": "oval:org.debian.oval:tst:1",
        "Comment": "Debian 9 is installed"
      }
    ]
  }
}